try ("a" > 2)
catch (exc) print("OK")
